<?xml version="1.0" ?>
<robot name="quadruped">

<material name="silver">
  <color rgba="0.700 0.700 0.700 1.000"/>
</material>

<material name="red">
  <color rgba="0.800 0.100 0.100 1.000"/>
</material>

<material name="white">
  <color rgba="1.000 1.000 1.000 1.000"/>
</material>

<material name="black">
  <color rgba="0.000 0.000 0.000 1.000"/>
</material>

<link name="base_link">
  <inertial>
    <origin xyz="2.9883837951735975e-06 0.039780613677239535 0.47410629746610494" rpy="0 0 0"/>
    <mass value="10.0"/>
    <inertia ixx="2.3637541744923034" iyy="0.5410784956750021" izz="2.6632359673082435" ixy="-2.0497891611652614e-06" iyz="9.783457932122097e-06" ixz="9.47338184325219e-11"/>
  </inertial>
  <visual>
    <origin xyz="0 0 0" rpy="0 0 0"/>
    <geometry>
      <mesh filename="meshes/base_link.stl" scale="0.001 0.001 0.001"/>
    </geometry>
    <material name="red"/>
    <material/>
  </visual>
  <collision>
    <origin xyz="0 0 0" rpy="0 0 0"/>
    <geometry>
      <mesh filename="meshes/base_link.stl" scale="0.001 0.001 0.001"/>
    </geometry>
  </collision>
</link>

<link name="hipFL1">
  <inertial>
    <origin xyz="0.028977503820283426 -0.039754030548852015 2.944583516462096e-07" rpy="0 0 0"/>
    <mass value="0.5"/>
    <inertia ixx="0.002342166894850506" iyy="0.0045940713120806165" izz="0.0037937417042337995" ixy="-2.6653779135875355e-05" iyz="2.7755575615628914e-17" ixz="0.0"/>
  </inertial>
  <visual>
    <origin xyz="-0.095003 0.225898 -0.474105" rpy="0 0 0"/>
    <geometry>
      <mesh filename="meshes/hipFL1.stl" scale="0.001 0.001 0.001"/>
    </geometry>
    <material name="silver"/>
    <material/>
  </visual>
  <collision>
    <origin xyz="-0.095003 0.225898 -0.474105" rpy="0 0 0"/>
    <geometry>
      <mesh filename="meshes/hipFL1.stl" scale="0.001 0.001 0.001"/>
    </geometry>
  </collision>
</link>

<link name="hipFR1">
  <inertial>
    <origin xyz="-0.028976862375981988 -0.039754030548852015 2.944583516462096e-07" rpy="0 0 0"/>
    <mass value="0.5"/>
    <inertia ixx="0.002342166894850506" iyy="0.0045940713120806165" izz="0.0037937417042337718" ixy="2.6653779135861477e-05" iyz="2.7755575615628914e-17" ixz="1.3877787807814457e-17"/>
  </inertial>
  <visual>
    <origin xyz="0.094997 0.225898 -0.474105" rpy="0 0 0"/>
    <geometry>
      <mesh filename="meshes/hipFR1.stl" scale="0.001 0.001 0.001"/>
    </geometry>
    <material name="silver"/>
    <material/>
  </visual>
  <collision>
    <origin xyz="0.094997 0.225898 -0.474105" rpy="0 0 0"/>
    <geometry>
      <mesh filename="meshes/hipFR1.stl" scale="0.001 0.001 0.001"/>
    </geometry>
  </collision>
</link>

<link name="hipBR1">
  <inertial>
    <origin xyz="-0.028976862375981988 0.039754605788009156 2.9445834553998296e-07" rpy="0 0 0"/>
    <mass value="0.5"/>
    <inertia ixx="0.0023421668948505614" iyy="0.0045940713120806165" izz="0.003793741704233855" ixy="-2.665377913584066e-05" iyz="0.0" ixz="1.3877787807814457e-17"/>
  </inertial>
  <visual>
    <origin xyz="0.094997 -0.374102 -0.474105" rpy="0 0 0"/>
    <geometry>
      <mesh filename="meshes/hipBR1.stl" scale="0.001 0.001 0.001"/>
    </geometry>
    <material name="silver"/>
    <material/>
  </visual>
  <collision>
    <origin xyz="0.094997 -0.374102 -0.474105" rpy="0 0 0"/>
    <geometry>
      <mesh filename="meshes/hipBR1.stl" scale="0.001 0.001 0.001"/>
    </geometry>
  </collision>
</link>

<link name="hipBL1">
  <inertial>
    <origin xyz="0.028977503820283426 0.03975460578800927 2.9445834565100526e-07" rpy="0 0 0"/>
    <mass value="0.5"/>
    <inertia ixx="0.0023421668948503394" iyy="0.0045940713120805055" izz="0.003793741704233744" ixy="2.6653779135882294e-05" iyz="0.0" ixz="0.0"/>
  </inertial>
  <visual>
    <origin xyz="-0.095003 -0.374102 -0.474105" rpy="0 0 0"/>
    <geometry>
      <mesh filename="meshes/hipBL1.stl" scale="0.001 0.001 0.001"/>
    </geometry>
    <material name="silver"/>
    <material/>
  </visual>
  <collision>
    <origin xyz="-0.095003 -0.374102 -0.474105" rpy="0 0 0"/>
    <geometry>
      <mesh filename="meshes/hipBL1.stl" scale="0.001 0.001 0.001"/>
    </geometry>
  </collision>
</link>

<link name="legFL1">
  <inertial>
    <origin xyz="0.020000320722150494 0.10090759547150757 -0.10090701339357744" rpy="0 0 0"/>
    <mass value="1.0"/>
    <inertia ixx="0.004772247916842248" iyy="0.002478868408036697" izz="0.00247886840803669" ixy="-2.7755575615628914e-17" iyz="0.0023133288373264164" ixz="-3.469446951953614e-17"/>
  </inertial>
  <visual>
    <origin xyz="-0.203003 0.255898 -0.474105" rpy="0 0 0"/>
    <geometry>
      <mesh filename="meshes/legFL1.stl" scale="0.001 0.001 0.001"/>
    </geometry>
    <material name="silver"/>
    <material/>
  </visual>
  <collision>
    <origin xyz="-0.203003 0.255898 -0.474105" rpy="0 0 0"/>
    <geometry>
      <mesh filename="meshes/legFL1.stl" scale="0.001 0.001 0.001"/>
    </geometry>
  </collision>
</link>

<link name="legBl1">
  <inertial>
    <origin xyz="0.020000320722150494 -0.10090702023235143 -0.10090701339358243" rpy="0 0 0"/>
    <mass value="1.0"/>
    <inertia ixx="0.004772247916842262" iyy="0.0024788684080366413" izz="0.0024788684080367523" ixy="-3.469446951953614e-17" iyz="-0.0023133288373264407" ixz="2.7755575615628914e-17"/>
  </inertial>
  <visual>
    <origin xyz="-0.203003 -0.404102 -0.474105" rpy="0 0 0"/>
    <geometry>
      <mesh filename="meshes/legBl1.stl" scale="0.001 0.001 0.001"/>
    </geometry>
    <material name="silver"/>
    <material/>
  </visual>
  <collision>
    <origin xyz="-0.203003 -0.404102 -0.474105" rpy="0 0 0"/>
    <geometry>
      <mesh filename="meshes/legBl1.stl" scale="0.001 0.001 0.001"/>
    </geometry>
  </collision>
</link>

<link name="legFR1">
  <inertial>
    <origin xyz="-0.019999679277849014 0.10090759547150766 -0.10090701339357716" rpy="0 0 0"/>
    <mass value="1.0"/>
    <inertia ixx="0.004772247916842248" iyy="0.002478868408036697" izz="0.002478868408036697" ixy="-2.7755575615628914e-17" iyz="0.002313328837326434" ixz="-2.0816681711721685e-17"/>
  </inertial>
  <visual>
    <origin xyz="0.202997 0.255898 -0.474105" rpy="0 0 0"/>
    <geometry>
      <mesh filename="meshes/legFR1.stl" scale="0.001 0.001 0.001"/>
    </geometry>
    <material name="silver"/>
    <material/>
  </visual>
  <collision>
    <origin xyz="0.202997 0.255898 -0.474105" rpy="0 0 0"/>
    <geometry>
      <mesh filename="meshes/legFR1.stl" scale="0.001 0.001 0.001"/>
    </geometry>
  </collision>
</link>

<link name="legBR1">
  <inertial>
    <origin xyz="-0.019999679277849014 -0.10090702023235143 -0.10090701339358227" rpy="0 0 0"/>
    <mass value="1.0"/>
    <inertia ixx="0.004772247916842262" iyy="0.0024788684080366413" izz="0.0024788684080367385" ixy="-2.0816681711721685e-17" iyz="-0.002313328837326427" ixz="2.7755575615628914e-17"/>
  </inertial>
  <visual>
    <origin xyz="0.202997 -0.404102 -0.474105" rpy="0 0 0"/>
    <geometry>
      <mesh filename="meshes/legBR1.stl" scale="0.001 0.001 0.001"/>
    </geometry>
    <material name="silver"/>
    <material/>
  </visual>
  <collision>
    <origin xyz="0.202997 -0.404102 -0.474105" rpy="0 0 0"/>
    <geometry>
      <mesh filename="meshes/legBR1.stl" scale="0.001 0.001 0.001"/>
    </geometry>
  </collision>
</link>

<link name="calfFL1">
  <inertial>
    <origin xyz="0.020000320722150494 -0.1590089499844665 -0.1590090118576217" rpy="0 0 0"/>
    <mass value="2.0"/>
    <inertia ixx="0.00498391749616179" iyy="0.002555772925631916" izz="0.0025557729256318953" ixy="-3.469446951953614e-18" iyz="-0.002421268606464846" ixz="0.0"/>
  </inertial>
  <visual>
    <origin xyz="-0.203003 0.043766 -0.261973" rpy="0 0 0"/>
    <geometry>
      <mesh filename="meshes/calfFL1.stl" scale="0.001 0.001 0.001"/>
    </geometry>
    <material name="white"/>
    <material/>
  </visual>
  <collision>
    <origin xyz="-0.203003 0.043766 -0.261973" rpy="0 0 0"/>
    <geometry>
      <mesh filename="meshes/calfFL1.stl" scale="0.001 0.001 0.001"/>
    </geometry>
  </collision>
</link>

<link name="calfBL1">
  <inertial>
    <origin xyz="0.020000320722150494 0.15900952522361986 -0.15900901185762717" rpy="0 0 0"/>
    <mass value="2.0"/>
    <inertia ixx="0.0049839174961618035" iyy="0.002555772925631951" izz="0.0025557729256318606" ixy="0.0" iyz="0.002421268606464846" ixz="3.469446951953614e-18"/>
  </inertial>
  <visual>
    <origin xyz="-0.203003 -0.19197 -0.261973" rpy="0 0 0"/>
    <geometry>
      <mesh filename="meshes/calfBL1.stl" scale="0.001 0.001 0.001"/>
    </geometry>
    <material name="white"/>
    <material/>
  </visual>
  <collision>
    <origin xyz="-0.203003 -0.19197 -0.261973" rpy="0 0 0"/>
    <geometry>
      <mesh filename="meshes/calfBL1.stl" scale="0.001 0.001 0.001"/>
    </geometry>
  </collision>
</link>

<link name="calfFR1">
  <inertial>
    <origin xyz="-0.019999679277849014 -0.1590089499844662 -0.1590090118576214" rpy="0 0 0"/>
    <mass value="2.0"/>
    <inertia ixx="0.004983917496161807" iyy="0.002555772925631916" izz="0.0025557729256319023" ixy="3.469446951953614e-18" iyz="-0.002421268606464846" ixz="-1.734723475976807e-18"/>
  </inertial>
  <visual>
    <origin xyz="0.202997 0.043766 -0.261973" rpy="0 0 0"/>
    <geometry>
      <mesh filename="meshes/calfFR1.stl" scale="0.001 0.001 0.001"/>
    </geometry>
    <material name="white"/>
    <material/>
  </visual>
  <collision>
    <origin xyz="0.202997 0.043766 -0.261973" rpy="0 0 0"/>
    <geometry>
      <mesh filename="meshes/calfFR1.stl" scale="0.001 0.001 0.001"/>
    </geometry>
  </collision>
</link>

<link name="calfBR1">
  <inertial>
    <origin xyz="-0.019999679277849014 0.15900952522362002 -0.1590090118576271" rpy="0 0 0"/>
    <mass value="2.0"/>
    <inertia ixx="0.004983917496161797" iyy="0.0025557729256319474" izz="0.0025557729256318606" ixy="-6.938893903907228e-18" iyz="0.002421268606464848" ixz="0.0"/>
  </inertial>
  <visual>
    <origin xyz="0.202997 -0.19197 -0.261973" rpy="0 0 0"/>
    <geometry>
      <mesh filename="meshes/calfBR1.stl" scale="0.001 0.001 0.001"/>
    </geometry>
    <material name="white"/>
    <material/>
  </visual>
  <collision>
    <origin xyz="0.202997 -0.19197 -0.261973" rpy="0 0 0"/>
    <geometry>
      <mesh filename="meshes/calfBR1.stl" scale="0.001 0.001 0.001"/>
    </geometry>
  </collision>
</link>

<link name="lidar1">
  <inertial>
    <origin xyz="-1.8093822187881343e-18 0.02500028761957951 0.002500294458353536" rpy="0 0 0"/>
    <mass value="0.01926679869584365"/>
    <inertia ixx="7.927484880054098e-07" iyy="7.927484880062771e-07" izz="1.505218648112372e-06" ixy="-1.0458300891968916e-21" iyz="0.0" ixz="8.71525074330748e-23"/>
  </inertial>
  <visual>
    <origin xyz="-0.0 0.425898 -0.569105" rpy="0 0 0"/>
    <geometry>
      <mesh filename="meshes/lidar1.stl" scale="0.001 0.001 0.001"/>
    </geometry>
    <material name="black"/>
    <material/>
  </visual>
  <collision>
    <origin xyz="-0.0 0.425898 -0.569105" rpy="0 0 0"/>
    <geometry>
      <mesh filename="meshes/lidar1.stl" scale="0.001 0.001 0.001"/>
    </geometry>
  </collision>
</link>

<joint name="hipjointFL" type="continuous">
  <origin xyz="0.095003 -0.225898 0.474105" rpy="0 0 0"/>
  <parent link="base_link"/>
  <child link="hipFL1"/>
  <axis xyz="-0.0 -1.0 0.0"/>
</joint>
<transmission name="hipjointFL_tran">
  <type>transmission_interface/SimpleTransmission</type>
  <joint name="hipjointFL">
    <hardwareInterface>PositionJointInterface</hardwareInterface>
  </joint>
  <actuator name="hipjointFL_actr">
    <hardwareInterface>PositionJointInterface</hardwareInterface>
    <mechanicalReduction>1</mechanicalReduction>
  </actuator>
</transmission>

<joint name="hipjointFR" type="continuous">
  <origin xyz="-0.094997 -0.225898 0.474105" rpy="0 0 0"/>
  <parent link="base_link"/>
  <child link="hipFR1"/>
  <axis xyz="-0.0 -1.0 0.0"/>
</joint>
<transmission name="hipjointFR_tran">
  <type>transmission_interface/SimpleTransmission</type>
  <joint name="hipjointFR">
    <hardwareInterface>PositionJointInterface</hardwareInterface>
  </joint>
  <actuator name="hipjointFR_actr">
    <hardwareInterface>PositionJointInterface</hardwareInterface>
    <mechanicalReduction>1</mechanicalReduction>
  </actuator>
</transmission>

<joint name="hipjointBR" type="continuous">
  <origin xyz="-0.094997 0.374102 0.474105" rpy="0 0 0"/>
  <parent link="base_link"/>
  <child link="hipBR1"/>
  <axis xyz="-0.0 -1.0 0.0"/>
</joint>
<transmission name="hipjointBR_tran">
  <type>transmission_interface/SimpleTransmission</type>
  <joint name="hipjointBR">
    <hardwareInterface>PositionJointInterface</hardwareInterface>
  </joint>
  <actuator name="hipjointBR_actr">
    <hardwareInterface>PositionJointInterface</hardwareInterface>
    <mechanicalReduction>1</mechanicalReduction>
  </actuator>
</transmission>

<joint name="hipjointBL" type="continuous">
  <origin xyz="0.095003 0.374102 0.474105" rpy="0 0 0"/>
  <parent link="base_link"/>
  <child link="hipBL1"/>
  <axis xyz="-0.0 -1.0 0.0"/>
</joint>
<transmission name="hipjointBL_tran">
  <type>transmission_interface/SimpleTransmission</type>
  <joint name="hipjointBL">
    <hardwareInterface>PositionJointInterface</hardwareInterface>
  </joint>
  <actuator name="hipjointBL_actr">
    <hardwareInterface>PositionJointInterface</hardwareInterface>
    <mechanicalReduction>1</mechanicalReduction>
  </actuator>
</transmission>

<joint name="Revolute_6" type="continuous">
  <origin xyz="0.108 -0.03 0.0" rpy="0 0 0"/>
  <parent link="hipFL1"/>
  <child link="legFL1"/>
  <axis xyz="1.0 0.0 0.0"/>
</joint>
<transmission name="Revolute_6_tran">
  <type>transmission_interface/SimpleTransmission</type>
  <joint name="Revolute_6">
    <hardwareInterface>PositionJointInterface</hardwareInterface>
  </joint>
  <actuator name="Revolute_6_actr">
    <hardwareInterface>PositionJointInterface</hardwareInterface>
    <mechanicalReduction>1</mechanicalReduction>
  </actuator>
</transmission>

<joint name="Revolute_7" type="continuous">
  <origin xyz="0.108 0.03 0.0" rpy="0 0 0"/>
  <parent link="hipBL1"/>
  <child link="legBl1"/>
  <axis xyz="1.0 -0.0 0.0"/>
</joint>
<transmission name="Revolute_7_tran">
  <type>transmission_interface/SimpleTransmission</type>
  <joint name="Revolute_7">
    <hardwareInterface>PositionJointInterface</hardwareInterface>
  </joint>
  <actuator name="Revolute_7_actr">
    <hardwareInterface>PositionJointInterface</hardwareInterface>
    <mechanicalReduction>1</mechanicalReduction>
  </actuator>
</transmission>

<joint name="Revolute_8" type="continuous">
  <origin xyz="-0.108 -0.03 0.0" rpy="0 0 0"/>
  <parent link="hipFR1"/>
  <child link="legFR1"/>
  <axis xyz="-1.0 0.0 0.0"/>
</joint>
<transmission name="Revolute_8_tran">
  <type>transmission_interface/SimpleTransmission</type>
  <joint name="Revolute_8">
    <hardwareInterface>PositionJointInterface</hardwareInterface>
  </joint>
  <actuator name="Revolute_8_actr">
    <hardwareInterface>PositionJointInterface</hardwareInterface>
    <mechanicalReduction>1</mechanicalReduction>
  </actuator>
</transmission>

<joint name="Revolute_9" type="continuous">
  <origin xyz="-0.108 0.03 0.0" rpy="0 0 0"/>
  <parent link="hipBR1"/>
  <child link="legBR1"/>
  <axis xyz="-1.0 0.0 -0.0"/>
</joint>
<transmission name="Revolute_9_tran">
  <type>transmission_interface/SimpleTransmission</type>
  <joint name="Revolute_9">
    <hardwareInterface>PositionJointInterface</hardwareInterface>
  </joint>
  <actuator name="Revolute_9_actr">
    <hardwareInterface>PositionJointInterface</hardwareInterface>
    <mechanicalReduction>1</mechanicalReduction>
  </actuator>
</transmission>

<joint name="Revolute_10" type="continuous">
  <origin xyz="0.0 0.212132 -0.212132" rpy="0 0 0"/>
  <parent link="legFL1"/>
  <child link="calfFL1"/>
  <axis xyz="1.0 -0.0 0.0"/>
</joint>
<transmission name="Revolute_10_tran">
  <type>transmission_interface/SimpleTransmission</type>
  <joint name="Revolute_10">
    <hardwareInterface>PositionJointInterface</hardwareInterface>
  </joint>
  <actuator name="Revolute_10_actr">
    <hardwareInterface>PositionJointInterface</hardwareInterface>
    <mechanicalReduction>1</mechanicalReduction>
  </actuator>
</transmission>

<joint name="Revolute_11" type="continuous">
  <origin xyz="0.0 -0.212132 -0.212132" rpy="0 0 0"/>
  <parent link="legBl1"/>
  <child link="calfBL1"/>
  <axis xyz="1.0 -0.0 0.0"/>
</joint>
<transmission name="Revolute_11_tran">
  <type>transmission_interface/SimpleTransmission</type>
  <joint name="Revolute_11">
    <hardwareInterface>PositionJointInterface</hardwareInterface>
  </joint>
  <actuator name="Revolute_11_actr">
    <hardwareInterface>PositionJointInterface</hardwareInterface>
    <mechanicalReduction>1</mechanicalReduction>
  </actuator>
</transmission>

<joint name="Revolute_12" type="continuous">
  <origin xyz="0.0 0.212132 -0.212132" rpy="0 0 0"/>
  <parent link="legFR1"/>
  <child link="calfFR1"/>
  <axis xyz="-1.0 0.0 0.0"/>
</joint>
<transmission name="Revolute_12_tran">
  <type>transmission_interface/SimpleTransmission</type>
  <joint name="Revolute_12">
    <hardwareInterface>PositionJointInterface</hardwareInterface>
  </joint>
  <actuator name="Revolute_12_actr">
    <hardwareInterface>PositionJointInterface</hardwareInterface>
    <mechanicalReduction>1</mechanicalReduction>
  </actuator>
</transmission>

<joint name="Revolute_13" type="continuous">
  <origin xyz="0.0 -0.212132 -0.212132" rpy="0 0 0"/>
  <parent link="legBR1"/>
  <child link="calfBR1"/>
  <axis xyz="-1.0 0.0 -0.0"/>
</joint>
<transmission name="Revolute_13_tran">
  <type>transmission_interface/SimpleTransmission</type>
  <joint name="Revolute_13">
    <hardwareInterface>PositionJointInterface</hardwareInterface>
  </joint>
  <actuator name="Revolute_13_actr">
    <hardwareInterface>PositionJointInterface</hardwareInterface>
    <mechanicalReduction>1</mechanicalReduction>
  </actuator>
</transmission>

<joint name="Rigid_14" type="fixed">
  <origin xyz="0.0 -0.425898 0.569105" rpy="0 0 -1.57079632679"/>
  <parent link="base_link"/>
  <child link="lidar1"/>
</joint>

</robot>
