<?xml version="1.0" ?>
<robot name="quadruped">

<material name="silver">
  <color rgba="0.700 0.700 0.700 1.000"/>
</material>

<material name="red">
  <color rgba="0.800 0.100 0.100 1.000"/>
</material>

<material name="white">
  <color rgba="1.000 1.000 1.000 1.000"/>
</material>

<material name="black">
  <color rgba="0.000 0.000 0.000 1.000"/>
</material>

<link name="base_link">
  <inertial>
    <origin xyz="2.9883837951735975e-06 -0.0352193863227606 -0.0008937025338958904" rpy="0 0 0"/>
    <mass value="5.0"/>
    <inertia ixx="2.3637541744923007" iyy="0.5410784956750033" izz="2.6632359673082435" ixy="-2.049789161165261e-06" iyz="9.783457932150286e-06" ixz="9.47338184441686e-11"/>
  </inertial>
  <visual>
    <origin xyz="0 0 0" rpy="0 0 0"/>
    <geometry>
      <mesh filename="meshes/base_link.stl" scale="0.001 0.001 0.001"/>
    </geometry>
    <material name="red"/>
    <material/>
  </visual>
  <collision>
    <origin xyz="0 0 0" rpy="0 0 0"/>
    <geometry>
      <mesh filename="meshes/base_link.stl" scale="0.001 0.001 0.001"/>
    </geometry>
  </collision>
</link>

<link name="hipFL1">
  <inertial>
    <origin xyz="0.028977503820283426 -0.03975403054885218 2.9445835077678787e-07" rpy="0 0 0"/>
    <mass value="0.5"/>
    <inertia ixx="0.002342166894850478" iyy="0.004594071312080641" izz="0.003793741704233744" ixy="-2.6653779135889233e-05" iyz="-5.421010862427522e-20" ixz="2.710505431213761e-20"/>
  </inertial>
  <visual>
    <origin xyz="-0.095003 0.300898 0.000895" rpy="0 0 0"/>
    <geometry>
      <mesh filename="meshes/hipFL1.stl" scale="0.001 0.001 0.001"/>
    </geometry>
    <material name="silver"/>
    <material/>
  </visual>
  <collision>
    <origin xyz="-0.095003 0.300898 0.000895" rpy="0 0 0"/>
    <geometry>
      <mesh filename="meshes/hipFL1.stl" scale="0.001 0.001 0.001"/>
    </geometry>
  </collision>
</link>

<link name="hipFR1">
  <inertial>
    <origin xyz="-0.028976862375981988 -0.03975403054885218 2.9445835078036574e-07" rpy="0 0 0"/>
    <mass value="0.5"/>
    <inertia ixx="0.002342166894850478" iyy="0.004594071312080651" izz="0.0037937417042337718" ixy="2.6653779135875355e-05" iyz="-5.421010862427522e-20" ixz="1.6263032587282567e-19"/>
  </inertial>
  <visual>
    <origin xyz="0.094997 0.300898 0.000895" rpy="0 0 0"/>
    <geometry>
      <mesh filename="meshes/hipFR1.stl" scale="0.001 0.001 0.001"/>
    </geometry>
    <material name="silver"/>
    <material/>
  </visual>
  <collision>
    <origin xyz="0.094997 0.300898 0.000895" rpy="0 0 0"/>
    <geometry>
      <mesh filename="meshes/hipFR1.stl" scale="0.001 0.001 0.001"/>
    </geometry>
  </collision>
</link>

<link name="hipBR1">
  <inertial>
    <origin xyz="-0.028976862375981988 0.039754605788009045 2.9445834466470654e-07" rpy="0 0 0"/>
    <mass value="0.5"/>
    <inertia ixx="0.002342166894850478" iyy="0.004594071312080634" izz="0.0037937417042337718" ixy="-2.6653779135861477e-05" iyz="-7.643625316022806e-18" ixz="8.131516293641283e-20"/>
  </inertial>
  <visual>
    <origin xyz="0.094997 -0.299102 0.000895" rpy="0 0 0"/>
    <geometry>
      <mesh filename="meshes/hipBR1.stl" scale="0.001 0.001 0.001"/>
    </geometry>
    <material name="silver"/>
    <material/>
  </visual>
  <collision>
    <origin xyz="0.094997 -0.299102 0.000895" rpy="0 0 0"/>
    <geometry>
      <mesh filename="meshes/hipBR1.stl" scale="0.001 0.001 0.001"/>
    </geometry>
  </collision>
</link>

<link name="hipBL1">
  <inertial>
    <origin xyz="0.028977503820283412 0.03975460578800899 2.9445834475046694e-07" rpy="0 0 0"/>
    <mass value="0.5"/>
    <inertia ixx="0.0023421668948504226" iyy="0.00459407131208063" izz="0.0037937417042337718" ixy="2.6653779135882294e-05" iyz="-7.697835424647081e-18" ixz="-2.981555974335137e-19"/>
  </inertial>
  <visual>
    <origin xyz="-0.095003 -0.299102 0.000895" rpy="0 0 0"/>
    <geometry>
      <mesh filename="meshes/hipBL1.stl" scale="0.001 0.001 0.001"/>
    </geometry>
    <material name="silver"/>
    <material/>
  </visual>
  <collision>
    <origin xyz="-0.095003 -0.299102 0.000895" rpy="0 0 0"/>
    <geometry>
      <mesh filename="meshes/hipBL1.stl" scale="0.001 0.001 0.001"/>
    </geometry>
  </collision>
</link>

<link name="legFL1">
  <inertial>
    <origin xyz="0.02000032072215055 0.10090759547150749 -0.10090701339357835" rpy="0 0 0"/>
    <mass value="2.5"/>
    <inertia ixx="0.004772247916842269" iyy="0.00247886840803669" izz="0.00247886840803669" ixy="-2.0816681711721685e-17" iyz="0.002313328837326425" ixz="-2.6020852139652106e-17"/>
  </inertial>
  <visual>
    <origin xyz="-0.203003 0.330898 0.000895" rpy="0 0 0"/>
    <geometry>
      <mesh filename="meshes/legFL1.stl" scale="0.001 0.001 0.001"/>
    </geometry>
    <material name="silver"/>
    <material/>
  </visual>
  <collision>
    <origin xyz="-0.203003 0.330898 0.000895" rpy="0 0 0"/>
    <geometry>
      <mesh filename="meshes/legFL1.stl" scale="0.001 0.001 0.001"/>
    </geometry>
  </collision>
</link>

<link name="legBl1">
  <inertial>
    <origin xyz="0.02000032072215069 -0.1009070202323514 -0.1009070133935831" rpy="0 0 0"/>
    <mass value="2.5"/>
    <inertia ixx="0.004772247916842262" iyy="0.0024788684080366413" izz="0.0024788684080367246" ixy="-3.122502256758253e-17" iyz="-0.0023133288373264234" ixz="2.42861286636753e-17"/>
  </inertial>
  <visual>
    <origin xyz="-0.203003 -0.329102 0.000895" rpy="0 0 0"/>
    <geometry>
      <mesh filename="meshes/legBl1.stl" scale="0.001 0.001 0.001"/>
    </geometry>
    <material name="silver"/>
    <material/>
  </visual>
  <collision>
    <origin xyz="-0.203003 -0.329102 0.000895" rpy="0 0 0"/>
    <geometry>
      <mesh filename="meshes/legBl1.stl" scale="0.001 0.001 0.001"/>
    </geometry>
  </collision>
</link>

<link name="legFR1">
  <inertial>
    <origin xyz="-0.019999679277848986 0.10090759547150754 -0.10090701339357805" rpy="0 0 0"/>
    <mass value="2.5"/>
    <inertia ixx="0.004772247916842248" iyy="0.0024788684080366864" izz="0.002478868408036697" ixy="-2.0816681711721685e-17" iyz="0.002313328837326427" ixz="-2.42861286636753e-17"/>
  </inertial>
  <visual>
    <origin xyz="0.202997 0.330898 0.000895" rpy="0 0 0"/>
    <geometry>
      <mesh filename="meshes/legFR1.stl" scale="0.001 0.001 0.001"/>
    </geometry>
    <material name="silver"/>
    <material/>
  </visual>
  <collision>
    <origin xyz="0.202997 0.330898 0.000895" rpy="0 0 0"/>
    <geometry>
      <mesh filename="meshes/legFR1.stl" scale="0.001 0.001 0.001"/>
    </geometry>
  </collision>
</link>

<link name="legBR1">
  <inertial>
    <origin xyz="-0.019999679277849014 -0.10090702023235151 -0.10090701339358316" rpy="0 0 0"/>
    <mass value="2.5"/>
    <inertia ixx="0.004772247916842262" iyy="0.0024788684080366587" izz="0.0024788684080367454" ixy="-2.42861286636753e-17" iyz="-0.0023133288373264234" ixz="2.7755575615628914e-17"/>
  </inertial>
  <visual>
    <origin xyz="0.202997 -0.329102 0.000895" rpy="0 0 0"/>
    <geometry>
      <mesh filename="meshes/legBR1.stl" scale="0.001 0.001 0.001"/>
    </geometry>
    <material name="silver"/>
    <material/>
  </visual>
  <collision>
    <origin xyz="0.202997 -0.329102 0.000895" rpy="0 0 0"/>
    <geometry>
      <mesh filename="meshes/legBR1.stl" scale="0.001 0.001 0.001"/>
    </geometry>
  </collision>
</link>

<link name="calfFL1">
  <inertial>
    <origin xyz="0.02000032072215055 -0.15900894998446663 -0.15900901185762253" rpy="0 0 0"/>
    <mass value="2.5"/>
    <inertia ixx="0.004983917496161783" iyy="0.002555772925631916" izz="0.0025557729256318953" ixy="-3.469446951953614e-18" iyz="-0.002421268606464841" ixz="0.0"/>
  </inertial>
  <visual>
    <origin xyz="-0.203003 0.118766 0.213027" rpy="0 0 0"/>
    <geometry>
      <mesh filename="meshes/calfFL1.stl" scale="0.001 0.001 0.001"/>
    </geometry>
    <material name="white"/>
    <material/>
  </visual>
  <collision>
    <origin xyz="-0.203003 0.118766 0.213027" rpy="0 0 0"/>
    <geometry>
      <mesh filename="meshes/calfFL1.stl" scale="0.001 0.001 0.001"/>
    </geometry>
  </collision>
</link>

<link name="calfBL1">
  <inertial>
    <origin xyz="0.020000320722150577 0.15900952522361989 -0.1590090118576277" rpy="0 0 0"/>
    <mass value="2.5"/>
    <inertia ixx="0.004983917496161824" iyy="0.002555772925631958" izz="0.0025557729256318745" ixy="0.0" iyz="0.002421268606464848" ixz="0.0"/>
  </inertial>
  <visual>
    <origin xyz="-0.203003 -0.11697 0.213027" rpy="0 0 0"/>
    <geometry>
      <mesh filename="meshes/calfBL1.stl" scale="0.001 0.001 0.001"/>
    </geometry>
    <material name="white"/>
    <material/>
  </visual>
  <collision>
    <origin xyz="-0.203003 -0.11697 0.213027" rpy="0 0 0"/>
    <geometry>
      <mesh filename="meshes/calfBL1.stl" scale="0.001 0.001 0.001"/>
    </geometry>
  </collision>
</link>

<link name="calfFR1">
  <inertial>
    <origin xyz="-0.019999679277849014 -0.15900894998446635 -0.15900901185762226" rpy="0 0 0"/>
    <mass value="2.5"/>
    <inertia ixx="0.0049839174961618105" iyy="0.0025557729256318884" izz="0.0025557729256318953" ixy="6.938893903907228e-18" iyz="-0.002421268606464848" ixz="6.938893903907228e-18"/>
  </inertial>
  <visual>
    <origin xyz="0.202997 0.118766 0.213027" rpy="0 0 0"/>
    <geometry>
      <mesh filename="meshes/calfFR1.stl" scale="0.001 0.001 0.001"/>
    </geometry>
    <material name="white"/>
    <material/>
  </visual>
  <collision>
    <origin xyz="0.202997 0.118766 0.213027" rpy="0 0 0"/>
    <geometry>
      <mesh filename="meshes/calfFR1.stl" scale="0.001 0.001 0.001"/>
    </geometry>
  </collision>
</link>

<link name="calfBR1">
  <inertial>
    <origin xyz="-0.019999679277849014 0.15900952522361983 -0.15900901185762803" rpy="0 0 0"/>
    <mass value="2.5"/>
    <inertia ixx="0.004983917496161797" iyy="0.002555772925631944" izz="0.0025557729256318468" ixy="-3.469446951953614e-18" iyz="0.002421268606464834" ixz="0.0"/>
  </inertial>
  <visual>
    <origin xyz="0.202997 -0.11697 0.213027" rpy="0 0 0"/>
    <geometry>
      <mesh filename="meshes/calfBR1.stl" scale="0.001 0.001 0.001"/>
    </geometry>
    <material name="white"/>
    <material/>
  </visual>
  <collision>
    <origin xyz="0.202997 -0.11697 0.213027" rpy="0 0 0"/>
    <geometry>
      <mesh filename="meshes/calfBR1.stl" scale="0.001 0.001 0.001"/>
    </geometry>
  </collision>
</link>

<link name="lidar1">
  <inertial>
    <origin xyz="-1.8093822187881343e-18 0.10000028761957935 0.4775002944583526" rpy="0 0 0"/>
    <mass value="0.02"/>
    <inertia ixx="7.927484880062771e-07" iyy="7.927484880060332e-07" izz="1.5052186481132393e-06" ixy="-1.0458300891968946e-21" iyz="0.0" ixz="8.715250743307518e-23"/>
  </inertial>
  <visual>
    <origin xyz="-0.0 0.575898 0.380895" rpy="0 0 0"/>
    <geometry>
      <mesh filename="meshes/lidar1.stl" scale="0.001 0.001 0.001"/>
    </geometry>
    <material name="black"/>
    <material/>
  </visual>
  <collision>
    <origin xyz="-0.0 0.575898 0.380895" rpy="0 0 0"/>
    <geometry>
      <mesh filename="meshes/lidar1.stl" scale="0.001 0.001 0.001"/>
    </geometry>
  </collision>
</link>

<joint name="hipjointFL" type="continuous">
  <origin xyz="0.095003 -0.300898 -0.000895" rpy="0 0 0"/>
  <parent link="base_link"/>
  <child link="hipFL1"/>
  <axis xyz="-0.0 -1.0 0.0"/>
</joint>
<transmission name="hipjointFL_tran">
  <type>transmission_interface/SimpleTransmission</type>
  <joint name="hipjointFL">
    <hardwareInterface>PositionJointInterface</hardwareInterface>
  </joint>
  <actuator name="hipjointFL_actr">
    <hardwareInterface>PositionJointInterface</hardwareInterface>
    <mechanicalReduction>1</mechanicalReduction>
  </actuator>
</transmission>

<joint name="hipjointFR" type="continuous">
  <origin xyz="-0.094997 -0.300898 -0.000895" rpy="0 0 0"/>
  <parent link="base_link"/>
  <child link="hipFR1"/>
  <axis xyz="-0.0 -1.0 0.0"/>
</joint>
<transmission name="hipjointFR_tran">
  <type>transmission_interface/SimpleTransmission</type>
  <joint name="hipjointFR">
    <hardwareInterface>PositionJointInterface</hardwareInterface>
  </joint>
  <actuator name="hipjointFR_actr">
    <hardwareInterface>PositionJointInterface</hardwareInterface>
    <mechanicalReduction>1</mechanicalReduction>
  </actuator>
</transmission>

<joint name="hipjointBR" type="continuous">
  <origin xyz="-0.094997 0.299102 -0.000895" rpy="0 0 0"/>
  <parent link="base_link"/>
  <child link="hipBR1"/>
  <axis xyz="-0.0 -1.0 0.0"/>
</joint>
<transmission name="hipjointBR_tran">
  <type>transmission_interface/SimpleTransmission</type>
  <joint name="hipjointBR">
    <hardwareInterface>PositionJointInterface</hardwareInterface>
  </joint>
  <actuator name="hipjointBR_actr">
    <hardwareInterface>PositionJointInterface</hardwareInterface>
    <mechanicalReduction>1</mechanicalReduction>
  </actuator>
</transmission>

<joint name="hipjointBL" type="continuous">
  <origin xyz="0.095003 0.299102 -0.000895" rpy="0 0 0"/>
  <parent link="base_link"/>
  <child link="hipBL1"/>
  <axis xyz="-0.0 -1.0 0.0"/>
</joint>
<transmission name="hipjointBL_tran">
  <type>transmission_interface/SimpleTransmission</type>
  <joint name="hipjointBL">
    <hardwareInterface>PositionJointInterface</hardwareInterface>
  </joint>
  <actuator name="hipjointBL_actr">
    <hardwareInterface>PositionJointInterface</hardwareInterface>
    <mechanicalReduction>1</mechanicalReduction>
  </actuator>
</transmission>

<joint name="Revolute_6" type="continuous">
  <origin xyz="0.108 -0.03 0.0" rpy="0 0 0"/>
  <parent link="hipFL1"/>
  <child link="legFL1"/>
  <axis xyz="1.0 0.0 0.0"/>
</joint>
<transmission name="Revolute_6_tran">
  <type>transmission_interface/SimpleTransmission</type>
  <joint name="Revolute_6">
    <hardwareInterface>PositionJointInterface</hardwareInterface>
  </joint>
  <actuator name="Revolute_6_actr">
    <hardwareInterface>PositionJointInterface</hardwareInterface>
    <mechanicalReduction>1</mechanicalReduction>
  </actuator>
</transmission>

<joint name="Revolute_7" type="continuous">
  <origin xyz="0.108 0.03 0.0" rpy="0 0 0"/>
  <parent link="hipBL1"/>
  <child link="legBl1"/>
  <axis xyz="1.0 -0.0 0.0"/>
</joint>
<transmission name="Revolute_7_tran">
  <type>transmission_interface/SimpleTransmission</type>
  <joint name="Revolute_7">
    <hardwareInterface>PositionJointInterface</hardwareInterface>
  </joint>
  <actuator name="Revolute_7_actr">
    <hardwareInterface>PositionJointInterface</hardwareInterface>
    <mechanicalReduction>1</mechanicalReduction>
  </actuator>
</transmission>

<joint name="Revolute_8" type="continuous">
  <origin xyz="-0.108 -0.03 0.0" rpy="0 0 0"/>
  <parent link="hipFR1"/>
  <child link="legFR1"/>
  <axis xyz="-1.0 0.0 0.0"/>
</joint>
<transmission name="Revolute_8_tran">
  <type>transmission_interface/SimpleTransmission</type>
  <joint name="Revolute_8">
    <hardwareInterface>PositionJointInterface</hardwareInterface>
  </joint>
  <actuator name="Revolute_8_actr">
    <hardwareInterface>PositionJointInterface</hardwareInterface>
    <mechanicalReduction>1</mechanicalReduction>
  </actuator>
</transmission>

<joint name="Revolute_9" type="continuous">
  <origin xyz="-0.108 0.03 0.0" rpy="0 0 0"/>
  <parent link="hipBR1"/>
  <child link="legBR1"/>
  <axis xyz="-1.0 0.0 -0.0"/>
</joint>
<transmission name="Revolute_9_tran">
  <type>transmission_interface/SimpleTransmission</type>
  <joint name="Revolute_9">
    <hardwareInterface>PositionJointInterface</hardwareInterface>
  </joint>
  <actuator name="Revolute_9_actr">
    <hardwareInterface>PositionJointInterface</hardwareInterface>
    <mechanicalReduction>1</mechanicalReduction>
  </actuator>
</transmission>

<joint name="Revolute_10" type="continuous">
  <origin xyz="0.0 0.212132 -0.212132" rpy="0 0 0"/>
  <parent link="legFL1"/>
  <child link="calfFL1"/>
  <axis xyz="1.0 -0.0 0.0"/>
</joint>
<transmission name="Revolute_10_tran">
  <type>transmission_interface/SimpleTransmission</type>
  <joint name="Revolute_10">
    <hardwareInterface>PositionJointInterface</hardwareInterface>
  </joint>
  <actuator name="Revolute_10_actr">
    <hardwareInterface>PositionJointInterface</hardwareInterface>
    <mechanicalReduction>1</mechanicalReduction>
  </actuator>
</transmission>

<joint name="Revolute_11" type="continuous">
  <origin xyz="0.0 -0.212132 -0.212132" rpy="0 0 0"/>
  <parent link="legBl1"/>
  <child link="calfBL1"/>
  <axis xyz="1.0 -0.0 -0.0"/>
</joint>
<transmission name="Revolute_11_tran">
  <type>transmission_interface/SimpleTransmission</type>
  <joint name="Revolute_11">
    <hardwareInterface>PositionJointInterface</hardwareInterface>
  </joint>
  <actuator name="Revolute_11_actr">
    <hardwareInterface>PositionJointInterface</hardwareInterface>
    <mechanicalReduction>1</mechanicalReduction>
  </actuator>
</transmission>

<joint name="Revolute_12" type="continuous">
  <origin xyz="0.0 0.212132 -0.212132" rpy="0 0 0"/>
  <parent link="legFR1"/>
  <child link="calfFR1"/>
  <axis xyz="-1.0 0.0 0.0"/>
</joint>
<transmission name="Revolute_12_tran">
  <type>transmission_interface/SimpleTransmission</type>
  <joint name="Revolute_12">
    <hardwareInterface>PositionJointInterface</hardwareInterface>
  </joint>
  <actuator name="Revolute_12_actr">
    <hardwareInterface>PositionJointInterface</hardwareInterface>
    <mechanicalReduction>1</mechanicalReduction>
  </actuator>
</transmission>

<joint name="Revolute_13" type="continuous">
  <origin xyz="0.0 -0.212132 -0.212132" rpy="0 0 0"/>
  <parent link="legBR1"/>
  <child link="calfBR1"/>
  <axis xyz="-1.0 0.0 -0.0"/>
</joint>
<transmission name="Revolute_13_tran">
  <type>transmission_interface/SimpleTransmission</type>
  <joint name="Revolute_13">
    <hardwareInterface>PositionJointInterface</hardwareInterface>
  </joint>
  <actuator name="Revolute_13_actr">
    <hardwareInterface>PositionJointInterface</hardwareInterface>
    <mechanicalReduction>1</mechanicalReduction>
  </actuator>
</transmission>

<joint name="Rigid_14" type="fixed">
  <origin xyz="0.0 -0.575898 -0.380895" rpy="0 0 0"/>
  <parent link="base_link"/>
  <child link="lidar1"/>
</joint>

</robot>
